Workbook
Name Slicer_ShipCountry: #N/A

Sheet EDA Q_1
B3: Average number of Orders per customers
L4: High repeat value customers by Total_sales
B6: Row Labels | C6: Count of OrderID
B7: ALFKI | C7: 6
B8: ANATR | C8: 4 | L8: CustomerID | M8: Sum of Total_sales
B9: ANTON | C9: 7 | L9: QUICK | M9: 110277.31
B10: AROUT | C10: 13 | L10: Grand Total | M10: 110277.31
B11: BERGS | C11: 18
B12: BLAUS | C12: 7
B13: BLONP | C13: 11
B14: BOLID | C14: 3
B15: BONAP | C15: 17
B16: BOTTM | C16: 14
B17: BSBEV | C17: 10
B18: CACTU | C18: 6
B19: CENTC | C19: 1
B20: CHOPS | C20: 8
B21: COMMI | C21: 5
B22: CONSH | C22: 3
... B96: Grand Total | C96: 830

Sheet EDA Q_2
E2: 2. How do customer order patterns vary by city or country
C6: Country / City | D6: Count of OrderID | F6: Country / City | G6: Sum of Total_sales
C7: Argentina | D7: 16 | F7: Argentina | G7: 8119.1
C8: Buenos Aires | D8: 16 | F8: Buenos Aires | G8: 8119.1
C9: Austria | D9: 40 | F9: Austria | G9: 128003.84
C10: Graz | D10: 30 | F10: Graz | G10: 104874.98
C11: Salzburg | D11: 10 | F11: Salzburg | G11: 23128.86
C12: Belgium | D12: 19 | F12: Belgium | G12: 33824.855
C13: Bruxelles | D13: 7 | F13: Bruxelles | G13: 9736.075
C14: Charleroi | D14: 12 | F14: Charleroi | G14: 24088.78
C15: Brazil | D15: 83 | F15: Brazil | G15: 106925.78
C16: Campinas | D16: 9 | F16: Campinas | G16: 8414.135
C17: Resende | D17: 9 | F17: Resende | G17: 6068.2
C18: Rio de Janeiro | D18: 34 | F18: Rio de Janeiro | G18: 51956.98
... C98: Grand Total | D98: 830 | F98: Grand Total | G98: 1265793

Sheet EDA Q_3
B3: 3. Can we cluster customers based on total spend, order count, and preferred categories?
D5: Customer Summary
B8: CustomerId | C8: Count of OrderID | D8: Sum of Total_revenue | E8: Preffered_Category | H8: Preffered_Category | I8: Count of CustomerId
B9: ALFKI | C9: 6 | D9: 4273 | E9: =_xlfn.XLOOKUP(B9,order_details[CustomerID],order_details[Category Name]) -> Produce | H9: Beverages | I9: 12
B10: ANATR | C10: 4 | D10: 1402.95 | E10: =_xlfn.XLOOKUP(B10,order_details[CustomerID],order_details[Category Name]) -> Dairy Products | H10: Condiments | I10: 11
B11: ANTON | C11: 7 | D11: 7023.9775 | E11: =_xlfn.XLOOKUP(B11,order_details[CustomerID],order_details[Category Name]) -> Dairy Products | H11: Confections | I11: 18
B12: AROUT | C12: 13 | D12: 13390.65 | E12: =_xlfn.XLOOKUP(B12,order_details[CustomerID],order_details[Category Name]) -> Beverages | H12: Dairy Products | I12: 15
B13: BERGS | C13: 18 | D13: 24927.577 | E13: =_xlfn.XLOOKUP(B13,order_details[CustomerID],order_details[Category Name]) -> Condiments | H13: Grains/Cereals | I13: 5
B14: BLAUS | C14: 7 | D14: 3239.8 | E14: =_xlfn.XLOOKUP(B14,order_details[CustomerID],order_details[Category Name]) -> Meat/Poultry | H14: Meat/Poultry | I14: 9
B15: BLONP | C15: 11 | D15: 18534.08 | E15: =_xlfn.XLOOKUP(B15,order_details[CustomerID],order_details[Category Name]) -> Meat/Poultry | H15: Produce | I15: 7
B16: BOLID | C16: 3 | D16: 4232.85 | E16: =_xlfn.XLOOKUP(B16,order_details[CustomerID],order_details[Category Name]) -> Condiments | H16: Seafood | I16: 12
B17: BONAP | C17: 17 | D17: 21963.253 | E17: =_xlfn.XLOOKUP(B17,order_details[CustomerID],order_details[Category Name]) -> Meat/Poultry | H17: (blank) | I17: 1
B18: BOTTM | C18: 14 | D18: 20801.6 | E18: =_xlfn.XLOOKUP(B18,order_details[CustomerID],order_details[Category Name]) -> Seafood | H18: Grand Total | I18: 90
B19: BSBEV | C19: 10 | D19: 6089.9 | E19: =_xlfn.XLOOKUP(B19,order_details[CustomerID],order_details[Category Name]) -> Condiments
B20: CACTU | C20: 6 | D20: 1814.8 | E20: =_xlfn.XLOOKUP(B20,order_details[CustomerID],order_details[Category Name]) -> Beverages
B21: CENTC | C21: 1 | D21: 100.8 | E21: =_xlfn.XLOOKUP(B21,order_details[CustomerID],order_details[Category Name]) -> Confections
B22: CHOPS | C22: 8 | D22: 12348.88 | E22: =_xlfn.XLOOKUP(B22,order_details[CustomerID],order_details[Category Name]) -> Beverages
B23: COMMI | C23: 5 | D23: 3810.75 | E23: =_xlfn.XLOOKUP(B23,order_details[CustomerID],order_details[Category Name]) -> Condiments
B24: CONSH | C24: 3 | D24: 1719.1 | E24: =_xlfn.XLOOKUP(B24,order_details[CustomerID],order_details[Category Name]) -> Beverages
B25: DRACD | C25: 6 | D25: 3763.21 | E25: =_xlfn.XLOOKUP(B25,order_details[CustomerID],order_details[Category Name]) -> Dairy Products
B26: DUMON | C26: 4 | D26: 1615.9 | E26: =_xlfn.XLOOKUP(B26,order_details[CustomerID],order_details[Category Name]) -> Grains/Cereals
B27: EASTC | C27: 8 | D27: 14761.035 | E27: =_xlfn.XLOOKUP(B27,order_details[CustomerID],order_details[Category Name]) -> Dairy Products
B28: ERNSH | C28: 30 | D28: 104874.98 | E28: =_xlfn.XLOOKUP(B28,order_details[CustomerID],order_details[Category Name]) -> Beverages
B29: FAMIA | C29: 7 | D29: 4107.55 | E29: =_xlfn.XLOOKUP(B29,order_details[CustomerID],order_details[Category Name]) -> Confections
B30: FOLIG | C30: 5 | D30: 11666.9 | E30: =_xlfn.XLOOKUP(B30,order_details[CustomerID],order_details[Category Name]) -> Seafood
... B97: WOLZA | C97: 7 | D97: 3531.95 | E97: =_xlfn.XLOOKUP(B97,order_details[CustomerID],order_details[Category Name]) -> Dairy Products
B98: Grand Total | C98: 830 | D98: 1265793

Sheet EDA Q_4
C3: . Which product categories or products contribute most to order revenue? Are there any correlations between orders and customer location or product category?
AB4: Country wise total order count Country and category wise total revenue generation
X7: Country and city wise revenue | AC7: Row Labels | AD7: Count of OrderID | AE7: Row Labels | AF7: Sum of Total_sales
AC8: Argentina | AD8: 16 | AE8: Argentina | AF8: 8119.1
B9: Category name | C9: Sum of Total_sales | Y9: Row Labels | Z9: Sum of Total_sales | AC9: Austria | AD9: 40 | AE9: Beverages | AF9: 1798
B10: Beverages | C10: 267868.18 | Y10: Argentina | Z10: 8119.1 | AC10: Belgium | AD10: 19 | AE10: Condiments | AF10: 907
B11: Condiments | C11: 106047.09 | Y11: Buenos Aires | Z11: 8119.1 | AC11: Brazil | AD11: 83 | AE11: Confections | AF11: 2135.1
B12: Confections | C12: 167357.22 | Y12: Austria | Z12: 128003.84 | AC12: Canada | AD12: 30 | AE12: Dairy Products | AF12: 1143.5
B13: Dairy Products | C13: 234507.29 | Y13: Graz | Z13: 104874.98 | AC13: Denmark | AD13: 18 | AE13: Grains/Cereals | AF13: 390
B14: Grains/Cereals | C14: 95744.588 | Y14: Salzburg | Z14: 23128.86 | AC14: Finland | AD14: 22 | AE14: Produce | AF14: 1139
B15: Meat/Poultry | C15: 163022.36 | Y15: Belgium | Z15: 33824.855 | AC15: France | AD15: 77 | AE15: Seafood | AF15: 606.5
B16: Produce | C16: 99984.58 | Y16: Bruxelles | Z16: 9736.075 | AC16: Germany | AD16: 122 | AE16: Austria | AF16: 128003.84
B17: Seafood | C17: 131261.74 | Y17: Charleroi | Z17: 24088.78 | AC17: Ireland | AD17: 19 | AE17: Beverages | AF17: 23317.3
B18: Grand Total | C18: 1265793 | Y18: Brazil | Z18: 106925.78 | AC18: Italy | AD18: 28 | AE18: Condiments | AF18: 15237.243
Y19: Campinas | Z19: 8414.135 | AC19: Mexico | AD19: 28 | AE19: Confections | AF19: 13534.408
Y20: Resende | Z20: 6068.2 | AC20: Norway | AD20: 6 | AE20: Dairy Products | AF20: 28106.74
B21: Category name | C21: Sum of Total_sales | Y21: Rio de Janeiro | Z21: 51956.98 | AC21: Poland | AD21: 7 | AE21: Grains/Cereals | AF21: 14527.7
B22: Beverages | C22: 1 | Y22: São Paulo | Z22: 40486.462 | AC22: Portugal | AD22: 13 | AE22: Meat/Poultry | AF22: 10821.556
B23: Condiments | C23: 6 | Y23: Canada | Z23: 50196.29 | AC23: Spain | AD23: 23 | AE23: Produce | AF23: 13120.667
B24: Confections | C24: 3 | Y24: Montréal | Z24: 28872.19 | AC24: Sweden | AD24: 37 | AE24: Seafood | AF24: 9338.225
B25: Dairy Products | C25: 2 | Y25: Tsawassen | Z25: 20801.6 | AC25: Switzerland | AD25: 18 | AE25: Belgium | AF25: 33824.855
B26: Grains/Cereals | C26: 8 | Y26: Vancouver | Z26: 522.5 | AC26: UK | AD26: 56 | AE26: Beverages | AF26: 5428.68
B27: Meat/Poultry | C27: 4 | Y27: Denmark | Z27: 32661.022 | AC27: USA | AD27: 122 | AE27: Condiments | AF27: 2454.795
B28: Produce | C28: 7 | Y28: Århus | Z28: 15843.925 | AC28: Venezuela | AD28: 46 | AE28: Confections | AF28: 7479.58
B29: Seafood | C29: 5 | Y29: København | Z29: 16817.097 | AC29: Grand Total | AD29: 830 | AE29: Dairy Products | AF29: 8660
B30: Grand Total | Y30: Finland | Z30: 18810.052 | AE30: Grains/Cereals | AF30: 3226
Y31: Helsinki | Z31: 3161.35 | AE31: Meat/Poultry | AF31: 2138.5
Y32: Oulu | Z32: 15648.702 | AE32: Produce | AF32: 3223.2
Y33: France | Z33: 81358.323 | AE33: Seafood | AF33: 1214.1
Y34: Lille | Z34: 11666.9 | AE34: Brazil | AF34: 106925.78
Y35: Lyon | Z35: 9182.43 | AE35: Beverages | AF35: 37193.445
Y36: Marseille | Z36: 21963.253 | AE36: Condiments | AF36: 11180.76
Y37: Nantes | Z37: 4788.06 | AE37: Confections | AF37: 11436.103
Y38: Paris | Z38: 2423.35 | AE38: Dairy Products | AF38: 15680.45
Y39: Reims | Z39: 1480 | AE39: Grains/Cereals | AF39: 6121.55
Y40: Strasbourg | Z40: 18534.08 | AE40: Meat/Poultry | AF40: 7563.114
Y41: Toulouse | Z41: 9328.2 | AE41: Produce | AF41: 4863.22
Y42: Versailles | Z42: 1992.05 | AE42: Seafood | AF42: 12887.135
... Y101: Grand Total | Z101: 1265793 | AE101: Dairy Products | AF101: 3995.14
AE102: Grains/Cereals | AF102: 1743.5
...

Sheet EDA Q_5
D3: 1. How frequently do different customer segments place orders?
B6: CustomerID | C6: Count of OrderID | D6: Customer segment | G6: Customer segment | H6: Average order per customer | I6: total ordres
B7: ALFKI | C7: 6 | D7: =IF(C7>=10,"Frequent Customers", IF(C7>=4,"Regular Customers", "Occasional Customers")) -> Regular Customers | G7: Frequent Customers | H7: 14.25641 | I7: 556
B8: ANATR | C8: 4 | D8: =IF(C8>=10,"Frequent Customers", IF(C8>=4,"Regular Customers", "Occasional Customers")) -> Regular Customers | G8: Occasional Customers | H8: 2.6 | I8: 26
B9: ANTON | C9: 7 | D9: =IF(C9>=10,"Frequent Customers", IF(C9>=4,"Regular Customers", "Occasional Customers")) -> Regular Customers | G9: Regular Customers | H9: 6.2 | I9: 248
B10: AROUT | C10: 13 | D10: =IF(C10>=10,"Frequent Customers", IF(C10>=4,"Regular Customers", "Occasional Customers")) -> Frequent Customers | G10: Grand Total | H10: 9.3258427 | I10: 830
B11: BERGS | C11: 18 | D11: =IF(C11>=10,"Frequent Customers", IF(C11>=4,"Regular Customers", "Occasional Customers")) -> Frequent Customers
B12: BLAUS | C12: 7 | D12: =IF(C12>=10,"Frequent Customers", IF(C12>=4,"Regular Customers", "Occasional Customers")) -> Regular Customers
B13: BLONP | C13: 11 | D13: =IF(C13>=10,"Frequent Customers", IF(C13>=4,"Regular Customers", "Occasional Customers")) -> Frequent Customers
B14: BOLID | C14: 3 | D14: =IF(C14>=10,"Frequent Customers", IF(C14>=4,"Regular Customers", "Occasional Customers")) -> Occasional Customers
B15: BONAP | C15: 17 | D15: =IF(C15>=10,"Frequent Customers", IF(C15>=4,"Regular Customers", "Occasional Customers")) -> Frequent Customers
B16: BOTTM | C16: 14 | D16: =IF(C16>=10,"Frequent Customers", IF(C16>=4,"Regular Customers", "Occasional Customers")) -> Frequent Customers
B17: BSBEV | C17: 10 | D17: =IF(C17>=10,"Frequent Customers", IF(C17>=4,"Regular Customers", "Occasional Customers")) -> Frequent Customers
B18: CACTU | C18: 6 | D18: =IF(C18>=10,"Frequent Customers", IF(C18>=4,"Regular Customers", "Occasional Customers")) -> Regular Customers
B19: CENTC | C19: 1 | D19: =IF(C19>=10,"Frequent Customers", IF(C19>=4,"Regular Customers", "Occasional Customers")) -> Occasional Customers
B20: CHOPS | C20: 8 | D20: =IF(C20>=10,"Frequent Customers", IF(C20>=4,"Regular Customers", "Occasional Customers")) -> Regular Customers
B21: COMMI | C21: 5 | D21: =IF(C21>=10,"Frequent Customers", IF(C21>=4,"Regular Customers", "Occasional Customers")) -> Regular Customers
B22: CONSH | C22: 3 | D22: =IF(C22>=10,"Frequent Customers", IF(C22>=4,"Regular Customers", "Occasional Customers")) -> Occasional Customers
... B95: WOLZA | C95: 7 | D95: =IF(C95>=10,"Frequent Customers", IF(C95>=4,"Regular Customers", "Occasional Customers")) -> Regular Customers
B96: Grand Total | C96: 830

Sheet EDA Q_6
C4: 1. What is the geographic and title-wise distribution of employees?
D11: Title | E11: Count of EmployeeID | G11: Count of EmployeeID | H11: Country
D12: Inside Sales Coordinator | E12: 1 | G12: Title | H12: UK | I12: USA | J12: Grand Total
D13: Sales Manager | E13: 1 | G13: Inside Sales Coordinator | I13: 1 | J13: 1
D14: Sales Representative | E14: 6 | G14: Sales Manager | H14: 1 | J14: 1
D15: Vice President, Sales | E15: 1 | G15: Sales Representative | H15: 3 | I15: 3 | J15: 6
D16: Grand Total | E16: 9 | G16: Vice President, Sales | I16: 1 | J16: 1
G17: Grand Total | H17: 4 | I17: 5 | J17: 9
D19: Country | E19: Count of EmployeeID
D20: UK | E20: 4
D21: USA | E21: 5
D22: Grand Total | E22: 9

Sheet EDA Q_7
G4: What trends can we observe in hire dates across employee titles?
Q8: Average Hire Date by Employee Title | Y8: Earliest and Latest Hire Date per Title
D10: Count of EmployeeID | E10: Title | L10: Title | M10: Average of Hire year
D11: Hire year | E11: Inside Sales Coordinator | F11: Sales Manager | G11: Sales Representative | H11: Vice President, Sales | I11: Grand Total | L11: Inside Sales Coordinator | M11: 1994
D12: 1992 | G12: 2 | H12: 1 | I12: 3 | L12: Sales Manager | M12: 1993
D13: 1993 | F13: 1 | G13: 2 | I13: 3 | L13: Sales Representative | M13: 1993
D14: 1994 | E14: 1 | G14: 2 | I14: 3 | L14: Vice President, Sales | M14: 1992
D15: Grand Total | E15: 1 | F15: 1 | G15: 6 | H15: 1 | I15: 9 | L15: Grand Total | M15: 1993
Q26: Employees Hired per Year by Title

Sheet EDA Q_8
C4: 1. What patterns exist in employee title and courtesy title distributions?
C10: title | D10: Count of EmployeeID
C11: Inside Sales Coordinator | D11: 1
C12: Ms. | D12: 1
C13: Sales Manager | D13: 1
C14: Mr. | D14: 1
C15: Sales Representative | D15: 6
C16: Mr. | D16: 2
C17: Mrs. | D17: 1
C18: Ms. | D18: 3
C19: Vice President, Sales | D19: 1
C20: Dr. | D20: 1
C21: Grand Total | D21: 9

Sheet EDA Q_9
A1: Are there correlations between product pricing, stock levels, and sales performance?
M3: Stock Levels vs Quantity Sold | S3: Unit Price vs Quantity Sold
B5: ProductID | C5: Quantity sold | D5: Unit price | E5: Units in stock | F5: Total Revenue
B6: 1 | C6: =SUMIFS(order_details[Quantity],order_details[ProductID],'EDA Q_9'!B6) -> 828 | D6: =_xlfn.XLOOKUP(B6,products[ProductID],products[UnitPrice]) -> 18 | E6: =_xlfn.XLOOKUP(B6,products[ProductID],products[UnitsInStock]) -> 39 | F6: =D6*C6 -> 14904 | H6: Price vs Sales Performance
B7: 2 | C7: =SUMIFS(order_details[Quantity],order_details[ProductID],'EDA Q_9'!B7) -> 1057 | D7: =_xlfn.XLOOKUP(B7,products[ProductID],products[UnitPrice]) -> 19 | E7: =_xlfn.XLOOKUP(B7,products[ProductID],products[UnitsInStock]) -> 17 | F7: =D7*C7 -> 20083 | H7: =CORREL(D6:D82,C6:C82) -> -0.03778077
B8: 3 | C8: =SUMIFS(order_details[Quantity],order_details[ProductID],'EDA Q_9'!B8) -> 328 | D8: =_xlfn.XLOOKUP(B8,products[ProductID],products[UnitPrice]) -> 10 | E8: =_xlfn.XLOOKUP(B8,products[ProductID],products[UnitsInStock]) -> 13 | F8: =D8*C8 -> 3280
B9: 4 | C9: =SUMIFS(order_details[Quantity],order_details[ProductID],'EDA Q_9'!B9) -> 453 | D9: =_xlfn.XLOOKUP(B9,products[ProductID],products[UnitPrice]) -> 22 | E9: =_xlfn.XLOOKUP(B9,products[ProductID],products[UnitsInStock]) -> 53 | F9: =D9*C9 -> 9966
B10: 5 | C10: =SUMIFS(order_details[Quantity],order_details[ProductID],'EDA Q_9'!B10) -> 298 | D10: =_xlfn.XLOOKUP(B10,products[ProductID],products[UnitPrice]) -> 21.35 | E10: =_xlfn.XLOOKUP(B10,products[ProductID],products[UnitsInStock]) -> 0 | F10: =D10*C10 -> 6362.3
B11: 6 | C11: =SUMIFS(order_details[Quantity],order_details[ProductID],'EDA Q_9'!B11) -> 301 | D11: =_xlfn.XLOOKUP(B11,products[ProductID],products[UnitPrice]) -> 25 | E11: =_xlfn.XLOOKUP(B11,products[ProductID],products[UnitsInStock]) -> 120 | F11: =D11*C11 -> 7525
B12: 7 | C12: =SUMIFS(order_details[Quantity],order_details[ProductID],'EDA Q_9'!B12) -> 763 | D12: =_xlfn.XLOOKUP(B12,products[ProductID],products[UnitPrice]) -> 30 | E12: =_xlfn.XLOOKUP(B12,products[ProductID],products[UnitsInStock]) -> 15 | F12: =D12*C12 -> 22890 | H12: Stock Level vs Sales Performance
B13: 8 | C13: =SUMIFS(order_details[Quantity],order_details[ProductID],'EDA Q_9'!B13) -> 372 | D13: =_xlfn.XLOOKUP(B13,products[ProductID],products[UnitPrice]) -> 40 | E13: =_xlfn.XLOOKUP(B13,products[ProductID],products[UnitsInStock]) -> 6 | F13: =D13*C13 -> 14880 | H13: =CORREL(E6:E82,C6:C82) -> -0.013413787
B14: 9 | C14: =SUMIFS(order_details[Quantity],order_details[ProductID],'EDA Q_9'!B14) -> 95 | D14: =_xlfn.XLOOKUP(B14,products[ProductID],products[UnitPrice]) -> 97 | E14: =_xlfn.XLOOKUP(B14,products[ProductID],products[UnitsInStock]) -> 29 | F14: =D14*C14 -> 9215
B15: 10 | C15: =SUMIFS(order_details[Quantity],order_details[ProductID],'EDA Q_9'!B15) -> 742 | D15: =_xlfn.XLOOKUP(B15,products[ProductID],products[UnitPrice]) -> 31 | E15: =_xlfn.XLOOKUP(B15,products[ProductID],products[UnitsInStock]) -> 31 | F15: =D15*C15 -> 23002
B16: 11 | C16: =SUMIFS(order_details[Quantity],order_details[ProductID],'EDA Q_9'!B16) -> 706 | D16: =_xlfn.XLOOKUP(B16,products[ProductID],products[UnitPrice]) -> 21 | E16: =_xlfn.XLOOKUP(B16,products[ProductID],products[UnitsInStock]) -> 22 | F16: =D16*C16 -> 14826
B17: 12 | C17: =SUMIFS(order_details[Quantity],order_details[ProductID],'EDA Q_9'!B17) -> 344 | D17: =_xlfn.XLOOKUP(B17,products[ProductID],products[UnitPrice]) -> 38 | E17: =_xlfn.XLOOKUP(B17,products[ProductID],products[UnitsInStock]) -> 86 | F17: =D17*C17 -> 13072 | H17: Price vs Stock Level
B18: 13 | C18: =SUMIFS(order_details[Quantity],order_details[ProductID],'EDA Q_9'!B18) -> 891 | D18: =_xlfn.XLOOKUP(B18,products[ProductID],products[UnitPrice]) -> 6 | E18: =_xlfn.XLOOKUP(B18,products[ProductID],products[UnitsInStock]) -> 24 | F18: =D18*C18 -> 5346 | H18: =CORREL(D6:D82,E6:E82) -> -0.17205534
B19: 14 | C19: =SUMIFS(order_details[Quantity],order_details[ProductID],'EDA Q_9'!B19) -> 404 | D19: =_xlfn.XLOOKUP(B19,products[ProductID],products[UnitPrice]) -> 23.25 | E19: =_xlfn.XLOOKUP(B19,products[ProductID],products[UnitsInStock]) -> 35 | F19: =D19*C19 -> 9393
B20: 15 | C20: =SUMIFS(order_details[Quantity],order_details[ProductID],'EDA Q_9'!B20) -> 122 | D20: =_xlfn.XLOOKUP(B20,products[ProductID],products[UnitPrice]) -> 15.5 | E20: =_xlfn.XLOOKUP(B20,products[ProductID],products[UnitsInStock]) -> 39 | F20: =D20*C20 -> 1891
B21: 16 | C21: =SUMIFS(order_details[Quantity],order_details[ProductID],'EDA Q_9'!B21) -> 1158 | D21: =_xlfn.XLOOKUP(B21,products[ProductID],products[UnitPrice]) -> 17.45 | E21: =_xlfn.XLOOKUP(B21,products[ProductID],products[UnitsInStock]) -> 29 | F21: =D21*C21 -> 20207.1
B22: 17 | C22: =SUMIFS(order_details[Quantity],order_details[ProductID],'EDA Q_9'!B22) -> 978 | D22: =_xlfn.XLOOKUP(B22,products[ProductID],products[UnitPrice]) -> 39 | E22: =_xlfn.XLOOKUP(B22,products[ProductID],products[UnitsInStock]) -> 0 | F22: =D22*C22 -> 38142
B23: 18 | C23: =SUMIFS(order_details[Quantity],order_details[ProductID],'EDA Q_9'!B23) -> 539 | D23: =_xlfn.XLOOKUP(B23,products[ProductID],products[UnitPrice]) -> 62.5 | E23: =_xlfn.XLOOKUP(B23,products[ProductID],products[UnitsInStock]) -> 42 | F23: =D23*C23 -> 33687.5
B24: 19 | C24: =SUMIFS(order_details[Quantity],order_details[ProductID],'EDA Q_9'!B24) -> 723 | D24: =_xlfn.XLOOKUP(B24,products[ProductID],products[UnitPrice]) -> 9.2 | E24: =_xlfn.XLOOKUP(B24,products[ProductID],products[UnitsInStock]) -> 25 | F24: =D24*C24 -> 6651.6
B25: 20 | C25: =SUMIFS(order_details[Quantity],order_details[ProductID],'EDA Q_9'!B25) -> 313 | D25: =_xlfn.XLOOKUP(B25,products[ProductID],products[UnitPrice]) -> 81 | E25: =_xlfn.XLOOKUP(B25,products[ProductID],products[UnitsInStock]) -> 40 | F25: =D25*C25 -> 25353
B26: 21 | C26: =SUMIFS(order_details[Quantity],order_details[ProductID],'EDA Q_9'!B26) -> 1016 | D26: =_xlfn.XLOOKUP(B26,products[ProductID],products[UnitPrice]) -> 10 | E26: =_xlfn.XLOOKUP(B26,products[ProductID],products[UnitsInStock]) -> 3 | F26: =D26*C26 -> 10160
B27: 22 | C27: =SUMIFS(order_details[Quantity],order_details[ProductID],'EDA Q_9'!B27) -> 348 | D27: =_xlfn.XLOOKUP(B27,products[ProductID],products[UnitPrice]) -> 21 | E27: =_xlfn.XLOOKUP(B27,products[ProductID],products[UnitsInStock]) -> 104 | F27: =D27*C27 -> 7308
B28: 23 | C28: =SUMIFS(order_details[Quantity],order_details[ProductID],'EDA Q_9'!B28) -> 580 | D28: =_xlfn.XLOOKUP(B28,products[ProductID],products[UnitPrice]) -> 9 | E28: =_xlfn.XLOOKUP(B28,products[ProductID],products[UnitsInStock]) -> 61 | F28: =D28*C28 -> 5220
B29: 24 | C29: =SUMIFS(order_details[Quantity],order_details[ProductID],'EDA Q_9'!B29) -> 1125 | D29: =_xlfn.XLOOKUP(B29,products[ProductID],products[UnitPrice]) -> 4.5 | E29: =_xlfn.XLOOKUP(B29,products[ProductID],products[UnitsInStock]) -> 20 | F29: =D29*C29 -> 5062.5
B30: 25 | C30: =SUMIFS(order_details[Quantity],order_details[ProductID],'EDA Q_9'!B30) -> 318 | D30: =_xlfn.XLOOKUP(B30,products[ProductID],products[UnitPrice]) -> 14 | E30: =_xlfn.XLOOKUP(B30,products[ProductID],products[UnitsInStock]) -> 76 | F30: =D30*C30 -> 4452
... B82: 77 | C82: =SUMIFS(order_details[Quantity],order_details[ProductID],'EDA Q_9'!B82) -> 791 | D82: =_xlfn.XLOOKUP(B82,products[ProductID],products[UnitPrice]) -> 13 | E82: =_xlfn.XLOOKUP(B82,products[ProductID],products[UnitsInStock]) -> 32 | F82: =D82*C82 -> 10283
B83: Grand Total

Sheet EDA Q_10
C3: How does product demand change over months or seasons?
B7: Row Labels | C7: Sum of Quantity | D7: Sum of Total_sales | G7: Year / Month | H7: Sum of Quantity
B8: 1994 | C8: 7381 | D8: 162844.34 | G8: 1994 | H8: 7381
B9: Aug | C9: 1462 | D9: 27861.895 | G9: Aug | H9: 1462
B10: Sep | C10: 1322 | D10: 25485.275 | G10: Sep | H10: 1322
B11: Oct | C11: 1124 | D11: 26381.4 | G11: Oct | H11: 1124
B12: Nov | C12: 1669 | D12: 35931.725 | G12: Nov | H12: 1669
B13: Dec | C13: 1804 | D13: 47184.045 | G13: Dec | H13: 1804
B14: 1995 | C14: 25007 | D14: 590926.4 | G14: 1995 | H14: 25007
B15: Jan | C15: 2200 | D15: 45239.63 | G15: Jan | H15: 2200
B16: Feb | C16: 1951 | D16: 52540.245 | G16: Feb | H16: 1951
B17: Mar | C17: 2582 | D17: 47201.46 | G17: Mar | H17: 2582
B18: Apr | C18: 1622 | D18: 35124.515 | G18: Apr | H18: 1622
B19: May | C19: 2060 | D19: 56455.657 | G19: May | H19: 2060
B20: Jun | C20: 2164 | D20: 53781.29 | G20: Jun | H20: 2164
B21: Jul | C21: 1635 | D21: 36362.803 | G21: Jul | H21: 1635
B22: Aug | C22: 2054 | D22: 51020.857 | G22: Aug | H22: 2054
B23: Sep | C23: 1861 | D23: 47287.67 | G23: Sep | H23: 1861
B24: Oct | C24: 2343 | D24: 55629.242 | G24: Oct | H24: 2343
B25: Nov | C25: 2657 | D25: 66461.426 | G25: Nov | H25: 2657
B26: Dec | C26: 1878 | D26: 43821.609 | G26: Dec | H26: 1878
B27: 1996 | C27: 18929 | D27: 512022.29 | G27: 1996 | H27: 18929
B28: Jan | C28: 2682 | D28: 71398.428 | G28: Jan | H28: 2682
B29: Feb | C29: 3293 | D29: 90117.711 | G29: Feb | H29: 3293
B30: Mar | C30: 3288 | D30: 103519.69 | G30: Mar | H30: 3288
B31: Apr | C31: 4065 | D31: 104854.16 | G31: Apr | H31: 4065
B32: May | C32: 4957 | D32: 129247.25 | G32: May | H32: 4957
B33: Jun | C33: 644 | D33: 12885.06 | G33: Jun | H33: 644
B34: Grand Total | C34: 51317 | D34: 1265793

Sheet EDA Q_12
D3: Are there any regional trends in supplier distribution and pricing?
B7: Supplier country | C7: No of suppliers | D7: Average of UnitPrice | E7: Max of UnitPrice | F7: Min of UnitPrice | H7: Supplier country | I7: Average of UnitPrice | S7: Supplier country | T7: No of suppliers
B8: Australia | C8: 8 | D8: 33.83125 | E8: 62.5 | F8: 7 | H8: Australia | I8: 33.83125 | S8: Australia | T8: 8
B9: Brazil | C9: 1 | D9: 4.5 | E9: 4.5 | F9: 4.5 | H9: Brazil | I9: 4.5 | S9: Brazil | T9: 1
B10: Canada | C10: 4 | D10: 27.3125 | E10: 49.3 | F10: 7.45 | H10: Canada | I10: 27.3125 | S10: Canada | T10: 4
B11: Denmark | C11: 2 | D11: 10.75 | E11: 12 | F11: 9.5 | H11: Denmark | I11: 10.75 | S11: Denmark | T11: 2
B12: Finland | C12: 3 | D12: 18.083333 | E12: 20 | F12: 16.25 | H12: Finland | I12: 18.083333 | S12: Finland | T12: 3
B13: France | C13: 5 | D13: 76.75 | E13: 263.5 | F13: 13.25 | H13: France | I13: 76.75 | S13: France | T13: 5
B14: Germany | C14: 9 | D14: 37.601111 | E14: 123.79 | F14: 7.75 | H14: Germany | I14: 37.601111 | S14: Germany | T14: 9
B15: Italy | C15: 5 | D15: 27.36 | E15: 38 | F15: 12.5 | H15: Italy | I15: 27.36 | S15: Italy | T15: 5
B16: Japan | C16: 6 | D16: 30.458333 | E16: 97 | F16: 6 | H16: Japan | I16: 30.458333 | S16: Japan | T16: 6
B17: Netherlands | C17: 2 | D17: 11.125 | E17: 12.75 | F17: 9.5 | H17: Netherlands | I17: 11.125 | S17: Netherlands | T17: 2
B18: Norway | C18: 3 | D18: 20 | E18: 36 | F18: 2.5 | H18: Norway | I18: 20 | S18: Norway | T18: 3
B19: Singapore | C19: 3 | D19: 26.483333 | E19: 46 | F19: 14 | H19: Singapore | I19: 26.483333 | S19: Singapore | T19: 3
... B24: USA | C24: 12 | D24: 20.870833 | E24: 40 | F24: 9.65 | H24: USA | I24: 20.870833 | S24: USA | T24: 12
B25: Grand Total | C25: 77 | D25: 28.866364 | E25: 263.5 | F25: 2.5 | H25: Grand Total | I25: 28.866364

Sheet EDA Q_13
D3: How are suppliers distributed across different product categories?
C5: ProductID | D5: SupplierID | E5: CategoryID | F5: Company name | G5: Category name
C6: 1 | D6: 1 | E6: 1 | F6: =_xlfn.XLOOKUP(D6,suppliers[SupplierID],suppliers[CompanyName]) -> Exotic Liquids | G6: =_xlfn.XLOOKUP(E6,categories[CategoryID],categories[CategoryName]) -> Beverages | I6: Category name | J6: Count of SupplierID
C7: 2 | D7: 1 | E7: 1 | F7: =_xlfn.XLOOKUP(D7,suppliers[SupplierID],suppliers[CompanyName]) -> Exotic Liquids | G7: =_xlfn.XLOOKUP(E7,categories[CategoryID],categories[CategoryName]) -> Beverages | I7: Beverages | J7: 12
C8: 3 | D8: 1 | E8: 2 | F8: =_xlfn.XLOOKUP(D8,suppliers[SupplierID],suppliers[CompanyName]) -> Exotic Liquids | G8: =_xlfn.XLOOKUP(E8,categories[CategoryID],categories[CategoryName]) -> Condiments | I8: Condiments | J8: 12
C9: 4 | D9: 2 | E9: 2 | F9: =_xlfn.XLOOKUP(D9,suppliers[SupplierID],suppliers[CompanyName]) -> New Orleans Cajun Delights | G9: =_xlfn.XLOOKUP(E9,categories[CategoryID],categories[CategoryName]) -> Condiments | I9: Confections | J9: 13
C10: 5 | D10: 2 | E10: 2 | F10: =_xlfn.XLOOKUP(D10,suppliers[SupplierID],suppliers[CompanyName]) -> New Orleans Cajun Delights | G10: =_xlfn.XLOOKUP(E10,categories[CategoryID],categories[CategoryName]) -> Condiments | I10: Dairy Products | J10: 10
C11: 6 | D11: 3 | E11: 2 | F11: =_xlfn.XLOOKUP(D11,suppliers[SupplierID],suppliers[CompanyName]) -> Grandma Kelly's Homestead | G11: =_xlfn.XLOOKUP(E11,categories[CategoryID],categories[CategoryName]) -> Condiments | I11: Grains/Cereals | J11: 7
C12: 7 | D12: 3 | E12: 7 | F12: =_xlfn.XLOOKUP(D12,suppliers[SupplierID],suppliers[CompanyName]) -> Grandma Kelly's Homestead | G12: =_xlfn.XLOOKUP(E12,categories[CategoryID],categories[CategoryName]) -> Produce | I12: Meat/Poultry | J12: 6
C13: 8 | D13: 3 | E13: 2 | F13: =_xlfn.XLOOKUP(D13,suppliers[SupplierID],suppliers[CompanyName]) -> Grandma Kelly's Homestead | G13: =_xlfn.XLOOKUP(E13,categories[CategoryID],categories[CategoryName]) -> Condiments | I13: Produce | J13: 5
C14: 9 | D14: 4 | E14: 6 | F14: =_xlfn.XLOOKUP(D14,suppliers[SupplierID],suppliers[CompanyName]) -> Tokyo Traders | G14: =_xlfn.XLOOKUP(E14,categories[CategoryID],categories[CategoryName]) -> Meat/Poultry | I14: Seafood | J14: 12
C15: 10 | D15: 4 | E15: 8 | F15: =_xlfn.XLOOKUP(D15,suppliers[SupplierID],suppliers[CompanyName]) -> Tokyo Traders | G15: =_xlfn.XLOOKUP(E15,categories[CategoryID],categories[CategoryName]) -> Seafood | I15: Grand Total | J15: 77
C16: 11 | D16: 5 | E16: 4 | F16: =_xlfn.XLOOKUP(D16,suppliers[SupplierID],suppliers[CompanyName]) -> Cooperativa de Quesos 'Las Cabras' | G16: =_xlfn.XLOOKUP(E16,categories[CategoryID],categories[CategoryName]) -> Dairy Products
C17: 12 | D17: 5 | E17: 4 | F17: =_xlfn.XLOOKUP(D17,suppliers[SupplierID],suppliers[CompanyName]) -> Cooperativa de Quesos 'Las Cabras' | G17: =_xlfn.XLOOKUP(E17,categories[CategoryID],categories[CategoryName]) -> Dairy Products
C18: 13 | D18: 6 | E18: 8 | F18: =_xlfn.XLOOKUP(D18,suppliers[SupplierID],suppliers[CompanyName]) -> Mayumi's | G18: =_xlfn.XLOOKUP(E18,categories[CategoryID],categories[CategoryName]) -> Seafood
C19: 14 | D19: 6 | E19: 7 | F19: =_xlfn.XLOOKUP(D19,suppliers[SupplierID],suppliers[CompanyName]) -> Mayumi's | G19: =_xlfn.XLOOKUP(E19,categories[CategoryID],categories[CategoryName]) -> Produce
C20: 15 | D20: 6 | E20: 2 | F20: =_xlfn.XLOOKUP(D20,suppliers[SupplierID],suppliers[CompanyName]) -> Mayumi's | G20: =_xlfn.XLOOKUP(E20,categories[CategoryID],categories[CategoryName]) -> Condiments
C21: 16 | D21: 7 | E21: 3 | F21: =_xlfn.XLOOKUP(D21,suppliers[SupplierID],suppliers[CompanyName]) -> Pavlova, Ltd. | G21: =_xlfn.XLOOKUP(E21,categories[CategoryID],categories[CategoryName]) -> Confections
C22: 17 | D22: 7 | E22: 6 | F22: =_xlfn.XLOOKUP(D22,suppliers[SupplierID],suppliers[CompanyName]) -> Pavlova, Ltd. | G22: =_xlfn.XLOOKUP(E22,categories[CategoryID],categories[CategoryName]) -> Meat/Poultry
C23: 18 | D23: 7 | E23: 8 | F23: =_xlfn.XLOOKUP(D23,suppliers[SupplierID],suppliers[CompanyName]) -> Pavlova, Ltd. | G23: =_xlfn.XLOOKUP(E23,categories[CategoryID],categories[CategoryName]) -> Seafood
C24: 19 | D24: 8 | E24: 3 | F24: =_xlfn.XLOOKUP(D24,suppliers[SupplierID],suppliers[CompanyName]) -> Specialty Biscuits, Ltd. | G24: =_xlfn.XLOOKUP(E24,categories[CategoryID],categories[CategoryName]) -> Confections
C25: 20 | D25: 8 | E25: 3 | F25: =_xlfn.XLOOKUP(D25,suppliers[SupplierID],suppliers[CompanyName]) -> Specialty Biscuits, Ltd. | G25: =_xlfn.XLOOKUP(E25,categories[CategoryID],categories[CategoryName]) -> Confections
C26: 21 | D26: 8 | E26: 3 | F26: =_xlfn.XLOOKUP(D26,suppliers[SupplierID],suppliers[CompanyName]) -> Specialty Biscuits, Ltd. | G26: =_xlfn.XLOOKUP(E26,categories[CategoryID],categories[CategoryName]) -> Confections
C27: 22 | D27: 9 | E27: 5 | F27: =_xlfn.XLOOKUP(D27,suppliers[SupplierID],suppliers[CompanyName]) -> PB Knäckebröd AB | G27: =_xlfn.XLOOKUP(E27,categories[CategoryID],categories[CategoryName]) -> Grains/Cereals
... C82: 77 | D82: 12 | E82: 2 | F82: =_xlfn.XLOOKUP(D82,suppliers[SupplierID],suppliers[CompanyName]) -> Plutzer Lebensmittelgroßmärkte AG | G82: =_xlfn.XLOOKUP(E82,categories[CategoryID],categories[CategoryName]) -> Condiments

Sheet EDA Q_14
B3: How do supplier pricing and categories relate across different regions?
B7: Supplier country | C7: Average of UnitPrice | D7: Count of ProductID | F7: Average of UnitPrice | G7: Column Labels
B8: Australia | C8: 33.83125 | D8: 8 | F8: Supplier country | G8: Beverages | H8: Condiments | I8: Confections | J8: Dairy Products | K8: Grains/Cereals | L8: Meat/Poultry | M8: Produce | N8: Seafood | O8: Grand Total
B9: Beverages | C9: 15 | D9: 1 | F9: Australia | G9: 15 | H9: 43.9 | I9: 17.45 | K9: 7 | L9: 35.9 | M9: 53 | N9: 62.5 | O9: 33.83125
B10: Condiments | C10: 43.9 | D10: 1 | F10: Brazil | G10: 4.5 | O10: 4.5
B11: Confections | C11: 17.45 | D11: 1 | F11: Canada | H11: 28.5 | I11: 49.3 | L11: 15.725 | O11: 27.3125
B12: Grains/Cereals | C12: 7 | D12: 1 | F12: Denmark | N12: 10.75 | O12: 10.75
B13: Meat/Poultry | C13: 35.9 | D13: 2 | F13: Finland | G13: 18 | I13: 18.125 | O13: 18.083333
B14: Produce | C14: 53 | D14: 1 | F14: France | G14: 140.75 | J14: 44.5 | N14: 13.25 | O14: 76.75
B15: Seafood | C15: 62.5 | D15: 1 | F15: Germany | G15: 7.75 | H15: 13 | I15: 29.71 | K15: 33.25 | L15: 123.79 | M15: 45.6 | N15: 25.89 | O15: 37.601111
B16: Brazil | C16: 4.5 | D16: 1 | F16: Italy | J16: 26.433333 | K16: 28.75 | O16: 27.36
B17: Beverages | C17: 4.5 | D17: 1 | F17: Japan | H17: 15.5 | L17: 97 | M17: 16.625 | N17: 18.5 | O17: 30.458333
B18: Canada | C18: 27.3125 | D18: 4 | F18: Netherlands | I18: 11.125 | O18: 11.125
B19: Condiments | C19: 28.5 | D19: 1 | F19: Norway | J19: 20 | O19: 20
B20: Confections | C20: 49.3 | D20: 1 | F20: Singapore | G20: 46 | H20: 19.45 | K20: 14 | O20: 26.483333
B21: Meat/Poultry | C21: 15.725 | D21: 2 | F21: Spain | J21: 29.5 | O21: 29.5
B22: Denmark | C22: 10.75 | D22: 2 | F22: Sweden | N22: 20 | O22: 20
B23: Seafood | C23: 10.75 | D23: 2 | F23: Sweden | K23: 15 | O23: 15
B24: Finland | C24: 18.083333 | D24: 3 | F24: UK | G24: 18.5 | H24: 10 | I24: 28.175 | O24: 22.814286
B25: Beverages | C25: 18 | D25: 1 | F25: USA | G25: 15.333333 | H25: 24.4 | M25: 30 | N25: 14.025 | O25: 20.870833
B26: Confections | C26: 18.125 | D26: 2 | F26: Grand Total | G26: 37.979167 | H26: 23.0625 | I26: 25.16 | J26: 28.73 | K26: 20.25 | L26: 54.006667 | M26: 32.37 | N26: 20.6825 | O26: 28.866364
B27: France | C27: 76.75 | D27: 5
B28: Beverages | C28: 140.75 | D28: 2
B29: Dairy Products | C29: 44.5 | D29: 2
B30: Seafood | C30: 13.25 | D30: 1
B31: Germany | C31: 37.601111 | D31: 9
B32: Beverages | C32: 7.75 | D32: 1
B33: Condiments | C33: 13 | D33: 1
B34: Confections | C34: 29.71 | D34: 3
B35: Grains/Cereals | C35: 33.25 | D35: 1
B36: Meat/Poultry | C36: 123.79 | D36: 1
B37: Produce | C37: 45.6 | D37: 1
B38: Seafood | C38: 25.89 | D38: 1
... B70: Grand Total | C70: 28.866364 | D70: 77

Sheet categories
A1: CategoryID | B1: CategoryName | C1: Description
A2: 1 | B2: Beverages | C2: Soft drinks, coffees, teas, beers, and ales
A3: 2 | B3: Condiments | C3: Sweet and savory sauces, relishes, spreads, and seasonings
A4: 3 | B4: Confections | C4: Desserts, candies, and sweet breads
A5: 4 | B5: Dairy Products | C5: Cheeses
A6: 5 | B6: Grains/Cereals | C6: Breads, crackers, pasta, and cereal
A7: 6 | B7: Meat/Poultry | C7: Prepared meats
A8: 7 | B8: Produce | C8: Dried fruit and bean curd
A9: 8 | B9: Seafood | C9: Seaweed and fish

Sheet customers
A1: Column1 | B1: Column2 | C1: Column3 | D1: Column4 | E1: Column5 | F1: Column6 | G1: Column7 | H1: Column8 | I1: Column9 | J1: Column10
A2: CustomerID | B2: CompanyName | C2: ContactName | D2: ContactTitle | E2: Address | F2: City | G2: Region | H2: PostalCode | I2: Country | J2: Phone
A3: ALFKI | B3: Alfreds Futterkiste | C3: Maria Anders | D3: Sales Representative | E3: Obere Str. 57 | F3: Berlin | H3: 12209 | I3: Germany | J3: 030-0074321
A4: ANATR | B4: Ana Trujillo Emparedados y helados | C4: Ana Trujillo | D4: Owner | E4: Avda. de la Constitución 2222 | F4: México D.F. | H4: 05021 | I4: Mexico | J4: (5) 555-4729
A5: ANTON | B5: Antonio Moreno Taquería | C5: Antonio Moreno | D5: Owner | E5: Mataderos 2312 | F5: México D.F. | H5: 05023 | I5: Mexico | J5: (5) 555-3932
A6: AROUT | B6: Around the Horn | C6: Thomas Hardy | D6: Sales Representative | E6: 120 Hanover Sq. | F6: London | H6: WA1 1DP | I6: UK | J6: (171) 555-7788
A7: BERGS | B7: Berglunds snabbköp | C7: Christina Berglund | D7: Order Administrator | E7: Berguvsvägen 8 | F7: Luleå | H7: S-958 22 | I7: Sweden | J7: 0921-12 34 65
A8: BLAUS | B8: Blauer See Delikatessen | C8: Hanna Moos | D8: Sales Representative | E8: Forsterstr. 57 | F8: Mannheim | H8: 68306 | I8: Germany | J8: 0621-08460
A9: BLONP | B9: Blondel père et fils | C9: Frédérique Citeaux | D9: Marketing Manager | E9: 24, place Kléber | F9: Strasbourg | H9: 67000 | I9: France | J9: 88.60.15.31
A10: BOLID | B10: Bólido Comidas preparadas | C10: Martín Sommer | D10: Owner | E10: C/ Araquil, 67 | F10: Madrid | H10: 28023 | I10: Spain | J10: (91) 555 22 82
A11: BONAP | B11: Bon app' | C11: Laurence Lebihan | D11: Owner | E11: 12, rue des Bouchers | F11: Marseille | H11: 13008 | I11: France | J11: 91.24.45.40
A12: BOTTM | B12: Bottom-Dollar Markets | C12: Elizabeth Lincoln | D12: Accounting Manager | E12: 23 Tsawassen Blvd. | F12: Tsawassen | G12: BC | H12: T2F 8M4 | I12: Canada | J12: (604) 555-4729
A13: BSBEV | B13: B's Beverages | C13: Victoria Ashworth | D13: Sales Representative | E13: Fauntleroy Circus | F13: London | H13: EC2 5NT | I13: UK | J13: (171) 555-1212
A14: CACTU | B14: Cactus Comidas para llevar | C14: Patricio Simpson | D14: Sales Agent | E14: Cerrito 333 | F14: Buenos Aires | H14: 1010 | I14: Argentina | J14: (1) 135-5555
A15: CENTC | B15: Centro comercial Moctezuma | C15: Francisco Chang | D15: Marketing Manager | E15: Sierras de Granada 9993 | F15: México D.F. | H15: 05022 | I15: Mexico | J15: (5) 555-3392
A16: CHOPS | B16: Chop-suey Chinese | C16: Yang Wang | D16: Owner | E16: Hauptstr. 29 | F16: Bern | H16: 3012 | I16: Switzerland | J16: 0452-076545
A17: COMMI | B17: Comércio Mineiro | C17: Pedro Afonso | D17: Sales Associate | E17: Av. dos Lusíadas, 23 | F17: São Paulo | G17: SP | H17: 05432-043 | I17: Brazil | J17: (11) 555-7647
A18: CONSH | B18: Consolidated Holdings | C18: Elizabeth Brown | D18: Sales Representative | E18: Berkeley Gardens 12 Brewery | F18: London | H18: WX1 6LT | I18: UK | J18: (171) 555-2282
A19: DRACD | B19: Drachenblut Delikatessen | C19: Sven Ottlieb | D19: Order Administrator | E19: Walserweg 21 | F19: Aachen | H19: 52066 | I19: Germany | J19: 0241-039123
A20: DUMON | B20: Du monde entier | C20: Janine Labrune | D20: Owner | E20: 67, rue des Cinquante Otages | F20: Nantes | H20: 44000 | I20: France | J20: 40.67.88.88
A21: EASTC | B21: Eastern Connection | C21: Ann Devon | D21: Sales Agent | E21: 35 King George | F21: London | H21: WX3 6FW | I21: UK | J21: (171) 555-0297
A22: ERNSH | B22: Ernst Handel | C22: Roland Mendel | D22: Sales Manager | E22: Kirchgasse 6 | F22: Graz | H22: 8010 | I22: Austria | J22: 7675-3425
A23: FAMIA | B23: Familia Arquibaldo | C23: Aria Cruz | D23: Marketing Assistant | E23: Rua Orós, 92 | F23: São Paulo | G23: SP | H23: 05442-030 | I23: Brazil | J23: (11) 555-9857
A24: FISSA | B24: FISSA Fabrica Inter. Salchichas S.A. | C24: Diego Roel | D24: Accounting Manager | E24: C/ Moralzarzal, 86 | F24: Madrid | H24: 28034 | I24: Spain | J24: (91) 555 94 44
A25: FOLIG | B25: Folies gourmandes | C25: Martine Rancé | D25: Assistant Sales Agent | E25: 184, chaussée de Tournai | F25: Lille | H25: 59000 | I25: France | J25: 20.16.10.16
A26: FOLKO | B26: Folk och fä HB | C26: Maria Larsson | D26: Owner | E26: Åkergatan 24 | F26: Bräcke | H26: S-844 67 | I26: Sweden | J26: 0695-34 67 21
A27: FRANK | B27: Frankenversand | C27: Peter Franken | D27: Marketing Manager | E27: Berliner Platz 43 | F27: München | H27: 80805 | I27: Germany | J27: 089-0877310
A28: FRANR | B28: France restauration | C28: Carine Schmitt | D28: Marketing Manager | E28: 54, rue Royale | F28: Nantes | H28: 44000 | I28: France | J28: 40.32.21.21
A29: FRANS | B29: Franchi S.p.A. | C29: Paolo Accorti | D29: Sales Representative | E29: Via Monte Bianco 34 | F29: Torino | H29: 10100 | I29: Italy | J29: 011-4988260
A30: FURIB | B30: Furia Bacalhau e Frutos do Mar | C30: Lino Rodriguez | D30: Sales Manager | E30: Jardim das rosas n. 32 | F30: Lisboa | H30: 1675 | I30: Portugal | J30: (1) 354-2534
A31: GALED | B31: Galería del gastrónomo | C31: Eduardo Saavedra | D31: Marketing Manager | E31: Rambla de Cataluña, 23 | F31: Barcelona | H31: 08022 | I31: Spain | J31: (93) 203 4560
A32: GODOS | B32: Godos Cocina Típica | C32: José Pedro Freyre | D32: Sales Manager | E32: C/ Romero, 33 | F32: Sevilla | H32: 41101 | I32: Spain | J32: (95) 555 82 82
A33: GOURL | B33: Gourmet Lanchonetes | C33: André Fonseca | D33: Sales Associate | E33: Av. Brasil, 442 | F33: Campinas | G33: SP | H33: 04876-786 | I33: Brazil | J33: (11) 555-9482
A34: GREAL | B34: Great Lakes Food Market | C34: Howard Snyder | D34: Marketing Manager | E34: 2732 Baker Blvd. | F34: Eugene | G34: OR | H34: 97403 | I34: USA | J34: (503) 555-7555
A35: GROSR | B35: GROSELLA-Restaurante | C35: Manuel Pereira | D35: Owner | E35: 5ª Ave. Los Palos Grandes | F35: Caracas | G35: DF | H35: 1081 | I35: Venezuela | J35: (2) 283-2951
A36: HANAR | B36: Hanari Carnes | C36: Mario Pontes | D36: Accounting Manager | E36: Rua do Paço, 67 | F36: Rio de Janeiro | G36: RJ | H36: 05454-876 | I36: Brazil | J36: (21) 555-0091
A37: HILAA | B37: HILARIÓN-Abastos | C37: Carlos Hernández | D37: Sales Representative | E37: Carrera 22 con Ave. Carlos Soublette #8-35 | F37: San Cristóbal | G37: Táchira | H37: 5022 | I37: Venezuela | J37: (5) 555-1340
A38: HUNGC | B38: Hungry Coyote Import Store | C38: Yoshi Latimer | D38: Sales Representative | E38: City Center Plaza 516 Main St. | F38: Elgin | G38: OR | H38: 97827 | I38: USA | J38: (503) 555-6874
A39: HUNGO | B39: Hungry Owl All-Night Grocers | C39: Patricia McKenna | D39: Sales Associate | E39: 8 Johnstown Road | F39: Cork | G39: Co. Cork | I39: Ireland | J39: 2967 542
A40: ISLAT | B40: Island Trading | C40: Helen Bennett | D40: Marketing Manager | E40: Garden House Crowther Way | F40: Cowes | G40: Isle of Wight | H40: PO31 7PJ | I40: UK | J40: (198) 555-8888
...

Sheet employees
A1: EmployeeID | B1: LastName | C1: FirstName | D1: Fullname | E1: Title | F1: TitleOfCourtesy | G1: BirthDate | H1: HireDate | I1: Address | J1: City | K1: Region | L1: PostalCode | M1: Country | N1: HomePhone | O1: Extension | P1: Notes | Q1: ReportsTo | R1: Hire year
A2: 1 | B2: Davolio | C2: Nancy | D2: =_xlfn.CONCAT(employees[[#This Row],[FirstName]], " ", employees[[#This Row],[LastName]]) -> Nancy Davolio | E2: Sales Representative | F2: Ms. | G2: 17875 | H2: 33725 | I2: 507 - 20th Ave. E. Apt. 2A | J2: Seattle | K2: WA | L2: 98122 | M2: USA | N2: (206) 555-9857 | O2: 5467 | P2: Education includes a BA in psychology from Colorado State University in 1970. She also completed "The Art of the Cold Call." Nancy is a member of Toastmasters International. | Q2: 2 | R2: =YEAR(employees[[#This Row],[HireDate]]) -> 1992
A3: 2 | B3: Fuller | C3: Andrew | D3: =_xlfn.CONCAT(employees[[#This Row],[FirstName]], " ", employees[[#This Row],[LastName]]) -> Andrew Fuller | E3: Vice President, Sales | F3: Dr. | G3: 19043 | H3: 33830 | I3: 908 W. Capital Way | J3: Tacoma | K3: WA | L3: 98401 | M3: USA | N3: (206) 555-9482 | O3: 3457 | P3: Andrew received his BTS commercial in 1974 and a Ph.D. in international marketing from the University of Dallas in 1981. He is fluent in French and Italian and reads German. He joined the company as a sales representative, was promoted to sales manager in January 1992 and to vice president of sales in March 1993. Andrew is a member of the Sales Management Roundtable, the Seattle Chamber of Commerce, and the Pacific Rim Importers Association. | R3: =YEAR(employees[[#This Row],[HireDate]]) -> 1992
A4: 3 | B4: Leverling | C4: Janet | D4: =_xlfn.CONCAT(employees[[#This Row],[FirstName]], " ", employees[[#This Row],[LastName]]) -> Janet Leverling | E4: Sales Representative | F4: Ms. | G4: 23253 | H4: 33695 | I4: 722 Moss Bay Blvd. | J4: Kirkland | K4: WA | L4: 98033 | M4: USA | N4: (206) 555-3412 | O4: 3355 | P4: Janet has a BS degree in chemistry from Boston College (1984). She has also completed a certificate program in food retailing management. Janet was hired as a sales associate in 1991 and promoted to sales representative in February 1992. | Q4: 2 | R4: =YEAR(employees[[#This Row],[HireDate]]) -> 1992
A5: 4 | B5: Peacock | C5: Margaret | D5: =_xlfn.CONCAT(employees[[#This Row],[FirstName]], " ", employees[[#This Row],[LastName]]) -> Margaret Peacock | E5: Sales Representative | F5: Mrs. | G5: 13777 | H5: 34092 | I5: 4110 Old Redmond Rd. | J5: Redmond | K5: WA | L5: 98052 | M5: USA | N5: (206) 555-8122 | O5: 5176 | P5: Margaret holds a BA in English literature from Concordia College (1958) and an MA from the American Institute of Culinary Arts (1966). She was assigned to the London office temporarily from July through November 1992. | Q5: 2 | R5: =YEAR(employees[[#This Row],[HireDate]]) -> 1993
A6: 5 | B6: Buchanan | C6: Steven | D6: =_xlfn.CONCAT(employees[[#This Row],[FirstName]], " ", employees[[#This Row],[LastName]]) -> Steven Buchanan | E6: Sales Manager | F6: Mr. | G6: 20152 | H6: 34259 | I6: 14 Garrett Hill | J6: London | L6: SW1 8JR | M6: UK | N6: (71) 555-4848 | O6: 3453 | P6: Steven Buchanan graduated from St. Andrews University, Scotland, with a BSC degree in 1976. Upon joining the company as a sales representative in 1992, he spent 6 months in an orientation program at the Seattle office and then returned to his permanent post in London. He was promoted to sales manager in March 1993. Mr. Buchanan has completed the courses "Successful Telemarketing" and "International Sales Management." He is fluent in French. | Q6: 2 | R6: =YEAR(employees[[#This Row],[HireDate]]) -> 1993
A7: 6 | B7: Suyama | C7: Michael | D7: =_xlfn.CONCAT(employees[[#This Row],[FirstName]], " ", employees[[#This Row],[LastName]]) -> Michael Suyama | E7: Sales Representative | F7: Mr. | G7: 23194 | H7: 34259 | I7: Coventry House Miner Rd. | J7: London | L7: EC2 7JR | M7: UK | N7: (71) 555-7773 | O7: 428 | P7: Michael is a graduate of Sussex University (MA, economics, 1983) and the University of California at Los Angeles (MBA, marketing, 1986). He has also taken the courses "Multi-Cultural Selling" and "Time Management for the Sales Professional." He is fluent in Japanese and can read and write French, Portuguese, and Spanish. | Q7: 5 | R7: =YEAR(employees[[#This Row],[HireDate]]) -> 1993
A8: 7 | B8: King | C8: Robert | D8: =_xlfn.CONCAT(employees[[#This Row],[FirstName]], " ", employees[[#This Row],[LastName]]) -> Robert King | E8: Sales Representative | F8: Mr. | G8: 22065 | H8: 34336 | I8: Edgeham Hollow Winchester Way | J8: London | L8: RG1 9SP | M8: UK | N8: (71) 555-5598 | O8: 465 | P8: Robert King served in the Peace Corps and traveled extensively before completing his degree in English at the University of Michigan in 1992, the year he joined the company. After completing a course entitled "Selling in Europe," he was transferred to the London office in March 1993. | Q8: 5 | R8: =YEAR(employees[[#This Row],[HireDate]]) -> 1994
A9: 8 | B9: Callahan | C9: Laura | D9: =_xlfn.CONCAT(employees[[#This Row],[FirstName]], " ", employees[[#This Row],[LastName]]) -> Laura Callahan | E9: Inside Sales Coordinator | F9: Ms. | G9: 21194 | H9: 34398 | I9: 4726 - 11th Ave. N.E. | J9: Seattle | K9: WA | L9: 98105 | M9: USA | N9: (206) 555-1189 | O9: 2344 | P9: Laura received a BA in psychology from the University of Washington. She has also completed a course in business French. She reads and writes French. | Q9: 2 | R9: =YEAR(employees[[#This Row],[HireDate]]) -> 1994
A10: 9 | B10: Dodsworth | C10: Anne | D10: =_xlfn.CONCAT(employees[[#This Row],[FirstName]], " ", employees[[#This Row],[LastName]]) -> Anne Dodsworth | E10: Sales Representative | F10: Ms. | G10: 24134 | H10: 34653 | I10: 7 Houndstooth Rd. | J10: London | L10: WG2 7LT | M10: UK | N10: (71) 555-4444 | O10: 452 | P10: Anne has a BA degree in English from St. Lawrence College. She is fluent in French and German. | Q10: 5 | R10: =YEAR(employees[[#This Row],[HireDate]]) -> 1994

Sheet orders
A1: OrderID | B1: CustomerID | C1: EmployeeID | D1: OrderDate | E1: RequiredDate | F1: ShippedDate | G1: ShipVia | H1: Freight | I1: ShipName | J1: ShipAddress | K1: ShipCity | L1: ShipRegion | M1: ShipPostalCode | N1: ShipCountry | O1: month | P1: month number | Q1: year
A2: 10248 | B2: VINET | C2: 5 | D2: 34550 | E2: 34578 | F2: 34562 | G2: 3 | H2: 32.38 | I2: Vins et alcools Chevalier | J2: 59 rue de l'Abbaye | K2: Reims | M2: 51100 | N2: France | O2: =TEXT(orders[[#This Row],[OrderDate]],"mmm") -> Aug | P2: =MONTH(orders[[#This Row],[OrderDate]]) -> 8 | Q2: =YEAR(orders[[#This Row],[OrderDate]]) -> 1994
A3: 10249 | B3: TOMSP | C3: 6 | D3: 34551 | E3: 34593 | F3: 34556 | G3: 1 | H3: 11.61 | I3: Toms Spezialitäten | J3: Luisenstr. 48 | K3: Münster | M3: 44087 | N3: Germany | O3: =TEXT(orders[[#This Row],[OrderDate]],"mmm") -> Aug | P3: =MONTH(orders[[#This Row],[OrderDate]]) -> 8 | Q3: =YEAR(orders[[#This Row],[OrderDate]]) -> 1994
A4: 10250 | B4: HANAR | C4: 4 | D4: 34554 | E4: 34582 | F4: 34558 | G4: 2 | H4: 65.83 | I4: Hanari Carnes | J4: Rua do Paço, 67 | K4: Rio de Janeiro | L4: RJ | M4: 05454-876 | N4: Brazil | O4: =TEXT(orders[[#This Row],[OrderDate]],"mmm") -> Aug | P4: =MONTH(orders[[#This Row],[OrderDate]]) -> 8 | Q4: =YEAR(orders[[#This Row],[OrderDate]]) -> 1994
A5: 10251 | B5: VICTE | C5: 3 | D5: 34554 | E5: 34582 | F5: 34561 | G5: 1 | H5: 41.34 | I5: Victuailles en stock | J5: 2, rue du Commerce | K5: Lyon | M5: 69004 | N5: France | O5: =TEXT(orders[[#This Row],[OrderDate]],"mmm") -> Aug | P5: =MONTH(orders[[#This Row],[OrderDate]]) -> 8 | Q5: =YEAR(orders[[#This Row],[OrderDate]]) -> 1994
A6: 10252 | B6: SUPRD | C6: 4 | D6: 34555 | E6: 34583 | F6: 34557 | G6: 2 | H6: 51.3 | I6: Suprêmes délices | J6: Boulevard Tirou, 255 | K6: Charleroi | M6: B-6000 | N6: Belgium | O6: =TEXT(orders[[#This Row],[OrderDate]],"mmm") -> Aug | P6: =MONTH(orders[[#This Row],[OrderDate]]) -> 8 | Q6: =YEAR(orders[[#This Row],[OrderDate]]) -> 1994
A7: 10253 | B7: HANAR | C7: 3 | D7: 34556 | E7: 34570 | F7: 34562 | G7: 2 | H7: 58.17 | I7: Hanari Carnes | J7: Rua do Paço, 67 | K7: Rio de Janeiro | L7: RJ | M7: 05454-876 | N7: Brazil | O7: =TEXT(orders[[#This Row],[OrderDate]],"mmm") -> Aug | P7: =MONTH(orders[[#This Row],[OrderDate]]) -> 8 | Q7: =YEAR(orders[[#This Row],[OrderDate]]) -> 1994
A8: 10254 | B8: CHOPS | C8: 5 | D8: 34557 | E8: 34585 | F8: 34569 | G8: 2 | H8: 22.98 | I8: Chop-suey Chinese | J8: Hauptstr. 31 | K8: Bern | M8: 3012 | N8: Switzerland | O8: =TEXT(orders[[#This Row],[OrderDate]],"mmm") -> Aug | P8: =MONTH(orders[[#This Row],[OrderDate]]) -> 8 | Q8: =YEAR(orders[[#This Row],[OrderDate]]) -> 1994
A9: 10255 | B9: RICSU | C9: 9 | D9: 34558 | E9: 34586 | F9: 34561 | G9: 3 | H9: 148.33 | I9: Richter Supermarkt | J9: Starenweg 5 | K9: Genève | M9: 1204 | N9: Switzerland | O9: =TEXT(orders[[#This Row],[OrderDate]],"mmm") -> Aug | P9: =MONTH(orders[[#This Row],[OrderDate]]) -> 8 | Q9: =YEAR(orders[[#This Row],[OrderDate]]) -> 1994
A10: 10256 | B10: WELLI | C10: 3 | D10: 34561 | E10: 34589 | F10: 34563 | G10: 2 | H10: 13.97 | I10: Wellington Importadora | J10: Rua do Mercado, 12 | K10: Resende | L10: SP | M10: 08737-363 | N10: Brazil | O10: =TEXT(orders[[#This Row],[OrderDate]],"mmm") -> Aug | P10: =MONTH(orders[[#This Row],[OrderDate]]) -> 8 | Q10: =YEAR(orders[[#This Row],[OrderDate]]) -> 1994
A11: 10257 | B11: HILAA | C11: 4 | D11: 34562 | E11: 34590 | F11: 34568 | G11: 3 | H11: 81.91 | I11: HILARIÓN-Abastos | J11: Carrera 22 con Ave. Carlos Soublette #8-35 | K11: San Cristóbal | L11: Táchira | M11: 5022 | N11: Venezuela | O11: =TEXT(orders[[#This Row],[OrderDate]],"mmm") -> Aug | P11: =MONTH(orders[[#This Row],[OrderDate]]) -> 8 | Q11: =YEAR(orders[[#This Row],[OrderDate]]) -> 1994
A12: 10258 | B12: ERNSH | C12: 1 | D12: 34563 | E12: 34591 | F12: 34569 | G12: 1 | H12: 140.51 | I12: Ernst Handel | J12: Kirchgasse 6 | K12: Graz | M12: 8010 | N12: Austria | O12: =TEXT(orders[[#This Row],[OrderDate]],"mmm") -> Aug | P12: =MONTH(orders[[#This Row],[OrderDate]]) -> 8 | Q12: =YEAR(orders[[#This Row],[OrderDate]]) -> 1994
A13: 10259 | B13: CENTC | C13: 4 | D13: 34564 | E13: 34592 | F13: 34571 | G13: 3 | H13: 3.25 | I13: Centro comercial Moctezuma | J13: Sierras de Granada 9993 | K13: México D.F. | M13: 05022 | N13: Mexico | O13: =TEXT(orders[[#This Row],[OrderDate]],"mmm") -> Aug | P13: =MONTH(orders[[#This Row],[OrderDate]]) -> 8 | Q13: =YEAR(orders[[#This Row],[OrderDate]]) -> 1994
A14: 10260 | B14: OTTIK | C14: 4 | D14: 34565 | E14: 34593 | F14: 34575 | G14: 1 | H14: 55.09 | I14: Ottilies Käseladen | J14: Mehrheimerstr. 369 | K14: Köln | M14: 50739 | N14: Germany | O14: =TEXT(orders[[#This Row],[OrderDate]],"mmm") -> Aug | P14: =MONTH(orders[[#This Row],[OrderDate]]) -> 8 | Q14: =YEAR(orders[[#This Row],[OrderDate]]) -> 1994
A15: 10261 | B15: QUEDE | C15: 4 | D15: 34565 | E15: 34593 | F15: 34576 | G15: 2 | H15: 3.05 | I15: Que Delícia | J15: Rua da Panificadora, 12 | K15: Rio de Janeiro | L15: RJ | M15: 02389-673 | N15: Brazil | O15: =TEXT(orders[[#This Row],[OrderDate]],"mmm") -> Aug | P15: =MONTH(orders[[#This Row],[OrderDate]]) -> 8 | Q15: =YEAR(orders[[#This Row],[OrderDate]]) -> 1994
A16: 10262 | B16: RATTC | C16: 8 | D16: 34568 | E16: 34596 | F16: 34571 | G16: 3 | H16: 48.29 | I16: Rattlesnake Canyon Grocery | J16: 2817 Milton Dr. | K16: Albuquerque | L16: NM | M16: 87110 | N16: USA | O16: =TEXT(orders[[#This Row],[OrderDate]],"mmm") -> Aug | P16: =MONTH(orders[[#This Row],[OrderDate]]) -> 8 | Q16: =YEAR(orders[[#This Row],[OrderDate]]) -> 1994
A17: 10263 | B17: ERNSH | C17: 9 | D17: 34569 | E17: 34597 | F17: 34577 | G17: 3 | H17: 146.06 | I17: Ernst Handel | J17: Kirchgasse 6 | K17: Graz | M17: 8010 | N17: Austria | O17: =TEXT(orders[[#This Row],[OrderDate]],"mmm") -> Aug | P17: =MONTH(orders[[#This Row],[OrderDate]]) -> 8 | Q17: =YEAR(orders[[#This Row],[OrderDate]]) -> 1994
A18: 10264 | B18: FOLKO | C18: 6 | D18: 34570 | E18: 34598 | F18: 34600 | G18: 3 | H18: 3.67 | I18: Folk och fä HB | J18: Åkergatan 24 | K18: Bräcke | M18: S-844 67 | N18: Sweden | O18: =TEXT(orders[[#This Row],[OrderDate]],"mmm") -> Aug | P18: =MONTH(orders[[#This Row],[OrderDate]]) -> 8 | Q18: =YEAR(orders[[#This Row],[OrderDate]]) -> 1994
A19: 10265 | B19: BLONP | C19: 2 | D19: 34571 | E19: 34599 | F19: 34589 | G19: 1 | H19: 55.28 | I19: Blondel père et fils | J19: 24, place Kléber | K19: Strasbourg | M19: 67000 | N19: France | O19: =TEXT(orders[[#This Row],[OrderDate]],"mmm") -> Aug | P19: =MONTH(orders[[#This Row],[OrderDate]]) -> 8 | Q19: =YEAR(orders[[#This Row],[OrderDate]]) -> 1994
A20: 10266 | B20: WARTH | C20: 3 | D20: 34572 | E20: 34614 | F20: 34577 | G20: 3 | H20: 25.73 | I20: Wartian Herkku | J20: Torikatu 38 | K20: Oulu | M20: 90110 | N20: Finland | O20: =TEXT(orders[[#This Row],[OrderDate]],"mmm") -> Aug | P20: =MONTH(orders[[#This Row],[OrderDate]]) -> 8 | Q20: =YEAR(orders[[#This Row],[OrderDate]]) -> 1994
A21: 10267 | B21: FRANK | C21: 4 | D21: 34575 | E21: 34603 | F21: 34583 | G21: 1 | H21: 208.58 | I21: Frankenversand | J21: Berliner Platz 43 | K21: München | M21: 80805 | N21: Germany | O21: =TEXT(orders[[#This Row],[OrderDate]],"mmm") -> Aug | P21: =MONTH(orders[[#This Row],[OrderDate]]) -> 8 | Q21: =YEAR(orders[[#This Row],[OrderDate]]) -> 1994
A22: 10268 | B22: GROSR | C22: 8 | D22: 34576 | E22: 34604 | F22: 34579 | G22: 3 | H22: 66.29 | I22: GROSELLA-Restaurante | J22: 5ª Ave. Los Palos Grandes | K22: Caracas | L22: DF | M22: 1081 | N22: Venezuela | O22: =TEXT(orders[[#This Row],[OrderDate]],"mmm") -> Aug | P22: =MONTH(orders[[#This Row],[OrderDate]]) -> 8 | Q22: =YEAR(orders[[#This Row],[OrderDate]]) -> 1994
A23: 10269 | B23: WHITC | C23: 5 | D23: 34577 | E23: 34591 | F23: 34586 | G23: 1 | H23: 4.56 | I23: White Clover Markets | J23: 1029 - 12th Ave. S. | K23: Seattle | L23: WA | M23: 98124 | N23: USA | O23: =TEXT(orders[[#This Row],[OrderDate]],"mmm") -> Aug | P23: =MONTH(orders[[#This Row],[OrderDate]]) -> 8 | Q23: =YEAR(orders[[#This Row],[OrderDate]]) -> 1994
A24: 10270 | B24: WARTH | C24: 1 | D24: 34578 | E24: 34606 | F24: 34579 | G24: 1 | H24: 136.54 | I24: Wartian Herkku | J24: Torikatu 38 | K24: Oulu | M24: 90110 | N24: Finland | O24: =TEXT(orders[[#This Row],[OrderDate]],"mmm") -> Sep | P24: =MONTH(orders[[#This Row],[OrderDate]]) -> 9 | Q24: =YEAR(orders[[#This Row],[OrderDate]]) -> 1994
A25: 10271 | B25: SPLIR | C25: 6 | D25: 34578 | E25: 34606 | F25: 34607 | G25: 2 | H25: 4.54 | I25: Split Rail Beer & Ale | J25: P.O. Box 555 | K25: Lander | L25: WY | M25: 82520 | N25: USA | O25: =TEXT(orders[[#This Row],[OrderDate]],"mmm") -> Sep | P25: =MONTH(orders[[#This Row],[OrderDate]]) -> 9 | Q25: =YEAR(orders[[#This Row],[OrderDate]]) -> 1994
A26: 10272 | B26: RATTC | C26: 6 | D26: 34579 | E26: 34607 | F26: 34583 | G26: 2 | H26: 98.03 | I26: Rattlesnake Canyon Grocery | J26: 2817 Milton Dr. | K26: Albuquerque | L26: NM | M26: 87110 | N26: USA | O26: =TEXT(orders[[#This Row],[OrderDate]],"mmm") -> Sep | P26: =MONTH(orders[[#This Row],[OrderDate]]) -> 9 | Q26: =YEAR(orders[[#This Row],[OrderDate]]) -> 1994
A27: 10273 | B27: QUICK | C27: 3 | D27: 34582 | E27: 34610 | F27: 34589 | G27: 3 | H27: 76.07 | I27: QUICK-Stop | J27: Taucherstraße 10 | K27: Cunewalde | M27: 01307 | N27: Germany | O27: =TEXT(orders[[#This Row],[OrderDate]],"mmm") -> Sep | P27: =MONTH(orders[[#This Row],[OrderDate]]) -> 9 | Q27: =YEAR(orders[[#This Row],[OrderDate]]) -> 1994
A28: 10274 | B28: VINET | C28: 6 | D28: 34583 | E28: 34611 | F28: 34593 | G28: 1 | H28: 6.01 | I28: Vins et alcools Chevalier | J28: 59 rue de l'Abbaye | K28: Reims | M28: 51100 | N28: France | O28: =TEXT(orders[[#This Row],[OrderDate]],"mmm") -> Sep | P28: =MONTH(orders[[#This Row],[OrderDate]]) -> 9 | Q28: =YEAR(orders[[#This Row],[OrderDate]]) -> 1994
A29: 10275 | B29: MAGAA | C29: 1 | D29: 34584 | E29: 34612 | F29: 34586 | G29: 1 | H29: 26.93 | I29: Magazzini Alimentari Riuniti | J29: Via Ludovico il Moro 22 | K29: Bergamo | M29: 24100 | N29: Italy | O29: =TEXT(orders[[#This Row],[OrderDate]],"mmm") -> Sep | P29: =MONTH(orders[[#This Row],[OrderDate]]) -> 9 | Q29: =YEAR(orders[[#This Row],[OrderDate]]) -> 1994
A30: 10276 | B30: TORTU | C30: 8 | D30: 34585 | E30: 34599 | F30: 34591 | G30: 3 | H30: 13.84 | I30: Tortuga Restaurante | J30: Avda. Azteca 123 | K30: México D.F. | M30: 05033 | N30: Mexico | O30: =TEXT(orders[[#This Row],[OrderDate]],"mmm") -> Sep | P30: =MONTH(orders[[#This Row],[OrderDate]]) -> 9 | Q30: =YEAR(orders[[#This Row],[OrderDate]]) -> 1994
A31: 10277 | B31: MORGK | C31: 2 | D31: 34586 | E31: 34614 | F31: 34590 | G31: 3 | H31: 125.77 | I31: Morgenstern Gesundkost | J31: Heerstr. 22 | K31: Leipzig | M31: 04179 | N31: Germany | O31: =TEXT(orders[[#This Row],[OrderDate]],"mmm") -> Sep | P31: =MONTH(orders[[#This Row],[OrderDate]]) -> 9 | Q31: =YEAR(orders[[#This Row],[OrderDate]]) -> 1994
A32: 10278 | B32: BERGS | C32: 8 | D32: 34589 | E32: 34617 | F32: 34593 | G32: 2 | H32: 92.69 | I32: Berglunds snabbköp | J32: Berguvsvägen 8 | K32: Luleå | M32: S-958 22 | N32: Sweden | O32: =TEXT(orders[[#This Row],[OrderDate]],"mmm") -> Sep | P32: =MONTH(orders[[#This Row],[OrderDate]]) -> 9 | Q32: =YEAR(orders[[#This Row],[OrderDate]]) -> 1994
A33: 10279 | B33: LEHMS | C33: 8 | D33: 34590 | E33: 34618 | F33: 34593 | G33: 2 | H33: 25.83 | I33: Lehmanns Marktstand | J33: Magazinweg 7 | K33: Frankfurt a.M. | M33: 60528 | N33: Germany | O33: =TEXT(orders[[#This Row],[OrderDate]],"mmm") -> Sep | P33: =MONTH(orders[[#This Row],[OrderDate]]) -> 9 | Q33: =YEAR(orders[[#This Row],[OrderDate]]) -> 1994
A34: 10280 | B34: BERGS | C34: 2 | D34: 34591 | E34: 34619 | F34: 34620 | G34: 1 | H34: 8.98 | I34: Berglunds snabbköp | J34: Berguvsvägen 8 | K34: Luleå | M34: S-958 22 | N34: Sweden | O34: =TEXT(orders[[#This Row],[OrderDate]],"mmm") -> Sep | P34: =MONTH(orders[[#This Row],[OrderDate]]) -> 9 | Q34: =YEAR(orders[[#This Row],[OrderDate]]) -> 1994
A35: 10281 | B35: ROMEY | C35: 4 | D35: 34591 | E35: 34605 | F35: 34598 | G35: 1 | H35: 2.94 | I35: Romero y tomillo | J35: Gran Vía, 1 | K35: Madrid | M35: 28001 | N35: Spain | O35: =TEXT(orders[[#This Row],[OrderDate]],"mmm") -> Sep | P35: =MONTH(orders[[#This Row],[OrderDate]]) -> 9 | Q35: =YEAR(orders[[#This Row],[OrderDate]]) -> 1994
A36: 10282 | B36: ROMEY | C36: 4 | D36: 34592 | E36: 34620 | F36: 34598 | G36: 1 | H36: 12.69 | I36: Romero y tomillo | J36: Gran Vía, 1 | K36: Madrid | M36: 28001 | N36: Spain | O36: =TEXT(orders[[#This Row],[OrderDate]],"mmm") -> Sep | P36: =MONTH(orders[[#This Row],[OrderDate]]) -> 9 | Q36: =YEAR(orders[[#This Row],[OrderDate]]) -> 1994
A37: 10283 | B37: LILAS | C37: 3 | D37: 34593 | E37: 34621 | F37: 34600 | G37: 3 | H37: 84.81 | I37: LILA-Supermercado | J37: Carrera 52 con Ave. Bolívar #65-98 Llano Largo | K37: Barquisimeto | L37: Lara | M37: 3508 | N37: Venezuela | O37: =TEXT(orders[[#This Row],[OrderDate]],"mmm") -> Sep | P37: =MONTH(orders[[#This Row],[OrderDate]]) -> 9 | Q37: =YEAR(orders[[#This Row],[OrderDate]]) -> 1994
A38: 10284 | B38: LEHMS | C38: 4 | D38: 34596 | E38: 34624 | F38: 34604 | G38: 1 | H38: 76.56 | I38: Lehmanns Marktstand | J38: Magazinweg 7 | K38: Frankfurt a.M. | M38: 60528 | N38: Germany | O38: =TEXT(orders[[#This Row],[OrderDate]],"mmm") -> Sep | P38: =MONTH(orders[[#This Row],[OrderDate]]) -> 9 | Q38: =YEAR(orders[[#This Row],[OrderDate]]) -> 1994
